2024-01-28 03:49:24,339 - root - ERROR - Error occurred
Traceback (most recent call last):
  File "/Users/michaeljones/Documents/Projects/Web Development/sautAI/.sautai/lib/python3.11/site-packages/urllib3/connection.py", line 203, in _new_conn
    sock = connection.create_connection(
           ^^^^^^^^^^^^^^^^^^^^^^^^^^^^^
  File "/Users/michaeljones/Documents/Projects/Web Development/sautAI/.sautai/lib/python3.11/site-packages/urllib3/util/connection.py", line 85, in create_connection
    raise err
  File "/Users/michaeljones/Documents/Projects/Web Development/sautAI/.sautai/lib/python3.11/site-packages/urllib3/util/connection.py", line 73, in create_connection
    sock.connect(sa)
ConnectionRefusedError: [Errno 61] Connection refused

The above exception was the direct cause of the following exception:

Traceback (most recent call last):
  File "/Users/michaeljones/Documents/Projects/Web Development/sautAI/.sautai/lib/python3.11/site-packages/urllib3/connectionpool.py", line 790, in urlopen
    response = self._make_request(
               ^^^^^^^^^^^^^^^^^^^
  File "/Users/michaeljones/Documents/Projects/Web Development/sautAI/.sautai/lib/python3.11/site-packages/urllib3/connectionpool.py", line 496, in _make_request
    conn.request(
  File "/Users/michaeljones/Documents/Projects/Web Development/sautAI/.sautai/lib/python3.11/site-packages/urllib3/connection.py", line 395, in request
    self.endheaders()
  File "/opt/homebrew/Cellar/python@3.11/3.11.7/Frameworks/Python.framework/Versions/3.11/lib/python3.11/http/client.py", line 1289, in endheaders
    self._send_output(message_body, encode_chunked=encode_chunked)
  File "/opt/homebrew/Cellar/python@3.11/3.11.7/Frameworks/Python.framework/Versions/3.11/lib/python3.11/http/client.py", line 1048, in _send_output
    self.send(msg)
  File "/opt/homebrew/Cellar/python@3.11/3.11.7/Frameworks/Python.framework/Versions/3.11/lib/python3.11/http/client.py", line 986, in send
    self.connect()
  File "/Users/michaeljones/Documents/Projects/Web Development/sautAI/.sautai/lib/python3.11/site-packages/urllib3/connection.py", line 243, in connect
    self.sock = self._new_conn()
                ^^^^^^^^^^^^^^^^
  File "/Users/michaeljones/Documents/Projects/Web Development/sautAI/.sautai/lib/python3.11/site-packages/urllib3/connection.py", line 218, in _new_conn
    raise NewConnectionError(
urllib3.exceptions.NewConnectionError: <urllib3.connection.HTTPConnection object at 0x130580b90>: Failed to establish a new connection: [Errno 61] Connection refused

The above exception was the direct cause of the following exception:

Traceback (most recent call last):
  File "/Users/michaeljones/Documents/Projects/Web Development/sautAI/.sautai/lib/python3.11/site-packages/requests/adapters.py", line 486, in send
    resp = conn.urlopen(
           ^^^^^^^^^^^^^
  File "/Users/michaeljones/Documents/Projects/Web Development/sautAI/.sautai/lib/python3.11/site-packages/urllib3/connectionpool.py", line 844, in urlopen
    retries = retries.increment(
              ^^^^^^^^^^^^^^^^^^
  File "/Users/michaeljones/Documents/Projects/Web Development/sautAI/.sautai/lib/python3.11/site-packages/urllib3/util/retry.py", line 515, in increment
    raise MaxRetryError(_pool, url, reason) from reason  # type: ignore[arg-type]
    ^^^^^^^^^^^^^^^^^^^^^^^^^^^^^^^^^^^^^^^^^^^^^^^^^^^
urllib3.exceptions.MaxRetryError: HTTPConnectionPool(host='127.0.0.1', port=8000): Max retries exceeded with url: /customer_dashboard/api/thread_history/?page=1 (Caused by NewConnectionError('<urllib3.connection.HTTPConnection object at 0x130580b90>: Failed to establish a new connection: [Errno 61] Connection refused'))

During handling of the above exception, another exception occurred:

Traceback (most recent call last):
  File "/Users/michaeljones/Documents/Projects/Web Development/sautAI/pages/2_history.py", line 53, in threads
    response = api_call_with_refresh(
               ^^^^^^^^^^^^^^^^^^^^^^
  File "/Users/michaeljones/Documents/Projects/Web Development/sautAI/utils.py", line 25, in api_call_with_refresh
    response = requests.request(method, url, json=data, headers=headers)
               ^^^^^^^^^^^^^^^^^^^^^^^^^^^^^^^^^^^^^^^^^^^^^^^^^^^^^^^^^
  File "/Users/michaeljones/Documents/Projects/Web Development/sautAI/.sautai/lib/python3.11/site-packages/requests/api.py", line 59, in request
    return session.request(method=method, url=url, **kwargs)
           ^^^^^^^^^^^^^^^^^^^^^^^^^^^^^^^^^^^^^^^^^^^^^^^^^
  File "/Users/michaeljones/Documents/Projects/Web Development/sautAI/.sautai/lib/python3.11/site-packages/requests/sessions.py", line 589, in request
    resp = self.send(prep, **send_kwargs)
           ^^^^^^^^^^^^^^^^^^^^^^^^^^^^^^
  File "/Users/michaeljones/Documents/Projects/Web Development/sautAI/.sautai/lib/python3.11/site-packages/requests/sessions.py", line 703, in send
    r = adapter.send(request, **kwargs)
        ^^^^^^^^^^^^^^^^^^^^^^^^^^^^^^^
  File "/Users/michaeljones/Documents/Projects/Web Development/sautAI/.sautai/lib/python3.11/site-packages/requests/adapters.py", line 519, in send
    raise ConnectionError(e, request=request)
requests.exceptions.ConnectionError: HTTPConnectionPool(host='127.0.0.1', port=8000): Max retries exceeded with url: /customer_dashboard/api/thread_history/?page=1 (Caused by NewConnectionError('<urllib3.connection.HTTPConnection object at 0x130580b90>: Failed to establish a new connection: [Errno 61] Connection refused'))
